Workbook

Sheet Ruter
A1: RuteID | B1: Rute R1 | C1: Segment | D1: Segmenttype | E1: Mode | F1: Fra | G1: Til | H1: Distanse km | I1: Gj.snitt Hastighet km/t | J1: Transporttid timer | K1: Terminaltid timer | L1: Ventetid (timer) | M1: Segementtid | N1: Omlastninger | O1: Grenseforsinkelse (timer) | P1: Dager reist | Q1: Routsecanner
A2: R1 | C2: 1 | D2: Main haul | E2: Sjø | F2: Karmøy | G2: Rostock | H2: 900 | I2: 28 | J2: =H2/I2 -> 32.142857 | K2: 12 | L2: 34 | M2: =J2+K2+L2+O2 -> 78.642857 | N2: 1 | O2: 0.5
A3: R1 | C3: 2 | D3: Main haul | E3: rail1 | F3: Rostock | G3: Bratislava | H3: 1200 | I3: 25 | J3: =H3/I3 -> 48 | K3: 6 | L3: =IF(E3="Sjø",18,IF(E3="Truck",0,24)) -> 24 | M3: =J3+K3+L3+O3 -> 78 | N3: 0 | O3: 0
A4: R1 | C4: 3 | D4: Terminal transfer | E4: Truck | F4: Terminal | G4: terminal | H4: 20 | I4: 60 | J4: =H4/I4 -> 0.33333333 | K4: 4 | L4: =IF(E4="Sjø",18,IF(E4="Truck",0,24)) -> 0 | M4: =J4+K4+L4+O4 -> 4.3333333 | N4: 1 | O4: 0
A5: R1 | C5: 4 | D5: Main haul | E5: rail2 | F5: Bratislava | G5: Koper | H5: 400 | I5: 25 | J5: =H5/I5 -> 16 | K5: 6 | L5: =IF(E5="Sjø",18,IF(E5="Truck",0,24)) -> 24 | M5: =J5+K5+L5+O5 -> 46 | N5: 0 | O5: 0
A6: R1 | C6: 5 | D6: Final haul | E6: rail3 | F6: Koper | G6: Beograd | H6: 500 | I6: 25 | J6: =H6/I6 -> 20 | K6: 4 | L6: =IF(E6="Sjø",18,IF(E6="Truck",0,24)) -> 24 | M6: =J6+K6+L6+O6 -> 51 | N6: 1 | O6: 3
B7: Totalt | C7: =COUNT(C2:C6) -> 5 | H7: =SUM(H2:H6) -> 3020 | J7: =SUM(J2:J6) -> 116.47619 | K7: =SUM(K2:K6) -> 32 | L7: =SUM(L2:L6) -> 106 | M7: =SUM(M2:M6) -> 257.97619 | N7: =SUM(N2:N6) -> 3 | O7: =SUM(O2:O6) -> 3.5 | P7: =M7/24 -> 10.749008 | Q7: 7.5 | R7: dager
B10: Rute R2 | C10: Segment | D10: Segmenttype | E10: Mode | F10: Fra | G10: Til | H10: Distanse km | I10: GJ Hastighet km/t | J10: Transporttid timer | K10: Terminaltid timer | L10: Ventetid (timer) | M10: Segementtid | N10: Omlastninger | O10: Grenseforsinkelse (timer) | P10: Dager reist | Q10: Routsecanner
A11: R2 | C11: 1 | D11: Main haul | E11: Sjø | F11: Karmøy | G11: Hamburg | H11: 900 | I11: 28 | J11: =H11/I11 -> 32.142857 | K11: 12 | L11: =IF(E11="Sjø",34,IF(E11="Truck",0,24)) -> 34 | M11: =J11+K11+L11+O11 -> 78.642857 | N11: 1 | O11: 0.5
A12: R2 | C12: 2 | D12: Main haul | E12: Rail | F12: Hamburg | G12: München | H12: 840 | I12: 25 | J12: =H12/I12 -> 33.6 | K12: 6 | L12: =IF(E12="Sjø",18,IF(E12="Truck",0,24)) -> 24 | M12: =J12+K12+L12+O12 -> 63.6 | N12: 0 | O12: 0
A13: R2 | C13: 3 | D13: Main haul | E13: Rail | F13: München | G13: Ljubljana | H13: 400 | I13: 25 | J13: =H13/I13 -> 16 | K13: 6 | L13: =IF(E13="Sjø",18,IF(E13="Truck",0,24)) -> 24 | M13: =J13+K13+L13+O13 -> 46 | N13: 0 | O13: 0
A14: R2 | C14: 4 | D14: Final haul | E14: Rail | F14: Ljubljana | G14: Beograd | H14: 550 | I14: 25 | J14: =H14/I14 -> 22 | K14: 4 | L14: =IF(E14="Sjø",18,IF(E14="Truck",0,24)) -> 24 | M14: =J14+K14+L14+O14 -> 53 | N14: 1 | O14: 3
B15: Totalt | C15: =COUNT(C11:C14) -> 4 | H15: =SUM(H11:H14) -> 2690 | J15: =SUM(J11:J14) -> 103.74286 | K15: =SUM(K11:K14) -> 28 | L15: =SUM(L11:L14) -> 106 | M15: =SUM(M11:M14) -> 241.24286 | N15: =SUM(N11:N14) -> 2 | O15: =SUM(O11:O14) -> 3.5 | P15: =M15/24 -> 10.051786
B21: Rute R3 | C21: Segment | D21: Segmenttype | E21: Mode | F21: Fra | G21: Til | H21: Distanse km | I21: GJ Hastighet km/t | J21: Transporttid timer | K21: Terminaltid timer | L21: Ventetid (timer) | M21: Segementtid | N21: Omlastninger | O21: Grenseforsinkelse (timer) | P21: Dager reist | Q21: Routsecanner
A22: R3 | C22: 1 | E22: Sjø | F22: Karmøy | G22: Rotterdam | H22: 700 | I22: 28 | J22: =H22/I22 -> 25 | K22: 12 | L22: =IF(E22="Sjø",34,IF(E22="Truck",0,24)) -> 34 | M22: =J22+K22+L22+O22 -> 71.5 | N22: 1 | O22: 0.5
A23: R3 | C23: 2 | E23: Rail | F23: Rotterdam | G23: Munchen | H23: 850 | I23: 25 | J23: =H23/I23 -> 34 | K23: 6 | L23: =IF(E23="Sjø",18,IF(E23="Truck",0,24)) -> 24 | M23: =J23+K23+L23+O23 -> 64 | N23: 0 | O23: 0
A24: R3 | C24: 3 | E24: Rail | F24: Munchen | G24: Ljubljana | H24: 400 | I24: 25 | J24: =H24/I24 -> 16 | K24: 6 | L24: =IF(E24="Sjø",18,IF(E24="Truck",0,24)) -> 24 | M24: =J24+K24+L24+O24 -> 46 | N24: 0 | O24: 0
A25: R3 | C25: 4 | E25: Rail | F25: Ljubljana | G25: Beograd | H25: 550 | I25: 25 | J25: =H25/I25 -> 22 | K25: 4 | L25: =IF(E25="Sjø",18,IF(E25="Truck",0,24)) -> 24 | M25: =J25+K25+L25+O25 -> 53 | N25: 1 | O25: 3
B26: Totalt | H26: =SUM(H22:H25) -> 2500 | J26: =SUM(J22:J25) -> 97 | K26: =SUM(K22:K25) -> 28 | L26: =SUM(L22:L25) -> 106 | M26: =SUM(M22:M25) -> 234.5 | N26: =SUM(N22:N25) -> 2 | O26: =SUM(O22:O25) -> 3.5 | P26: =M26/24 -> 9.7708333 | Q26: 9 | R26: dager
B31: Rute R4 | C31: Segment | D31: Segmenttype | E31: Mode | F31: Fra | G31: Til | H31: Distanse km | I31: GJ Hastighet km/t | J31: Transporttid timer | K31: Terminaltid timer | L31: Ventetid (timer) | M31: Segementtid | N31: Omlastninger | O31: Grenseforsinkelse (timer) | P31: Dager reist | Q31: Routsecanner
A32: R4 | C32: 1 | E32: Sjø | F32: Karmøy | G32: Rotterdam | H32: 700 | I32: 28 | J32: =H32/I32 -> 25 | K32: 12 | L32: =IF(E32="Sjø",34,IF(E32="Truck",0,24)) -> 34 | M32: =J32+K32+L32+O32 -> 71.5 | N32: 1 | O32: 0.5
A33: R4 | C33: 2 | E33: Rail | F33: Rotterdam | G33: Wien | H33: 1100 | I33: 25 | J33: =H33/I33 -> 44 | K33: 6 | L33: =IF(E33="Sjø",18,IF(E33="Truck",0,24)) -> 24 | M33: =J33+K33+L33+O33 -> 74 | N33: 0 | O33: 0
A34: R4 | C34: 3 | E34: Rail | F34: Wien | G34: Koper | H34: 500 | I34: 25 | J34: =H34/I34 -> 20 | K34: 6 | L34: =IF(E34="Sjø",18,IF(E34="Truck",0,24)) -> 24 | M34: =J34+K34+L34+O34 -> 50 | N34: 0 | O34: 0
A35: R4 | C35: 4 | E35: Rail | F35: Koper | G35: Beograd | H35: 600 | I35: 25 | J35: =H35/I35 -> 24 | K35: 4 | L35: =IF(E35="Sjø",18,IF(E35="Truck",0,24)) -> 24 | M35: =J35+K35+L35+O35 -> 55 | N35: 1 | O35: 3
B36: Totalt | H36: =SUM(H32:H35) -> 2900 | J36: =SUM(J32:J35) -> 113 | K36: =SUM(K32:K35) -> 28 | L36: =SUM(L32:L35) -> 106 | M36: =SUM(M32:M35) -> 250.5 | N36: =SUM(N32:N35) -> 2 | O36: =SUM(O32:O35) -> 3.5 | P36: =M36/24 -> 10.4375 | Q36: 7 | R36: dagaer
B39: Rute R5 | C39: Segment | D39: Segmenttype | E39: Mode | F39: Fra | G39: Til | H39: Distanse km | I39: GJ Hastighet km/t | J39: Transporttid timer | K39: Terminaltid timer | L39: Ventetid (timer) | M39: Segementtid | N39: Omlastninger | O39: Grenseforsinkelse (timer) | P39: Dager reist | Q39: Routsecanner
A40: R5 | C40: 1 | D40: Main haul | E40: Sjø | F40: Karmøy | G40: Rotterdam | H40: 700 | I40: 28 | J40: =H40/I40 -> 25 | K40: 12 | L40: =IF(E40="Sjø",34,IF(E40="Truck",0,24)) -> 34 | M40: =J40+K40+L40+O40 -> 71.5 | N40: 1 | O40: 0.5
A41: R5 | C41: 2 | D41: Main haul | E41: Sjø | F41: Rotterdam | G41: Bar (Montenegro) | H41: 3800 | I41: 33 | J41: =H41/I41 -> 115.15152 | K41: 12 | L41: =IF(E41="Sjø",34,IF(E41="Truck",0,24)) -> 34 | M41: =J41+K41+L41+O41 -> 161.15152 | N41: 1 | O41: 0
A42: R5 | C42: 3 | D42: Final haul | E42: Truck | F42: Bar (Montenegro) | G42: Beograd | H42: 476 | I42: 60 | J42: =H42/I42 -> 7.9333333 | K42: 4 | L42: =IF(E42="Sjø",18,IF(E42="Truck",0,24)) -> 0 | M42: =J42+K42+L42+O42 -> 14.933333 | N42: 1 | O42: 3
B43: Totalt | C43: =COUNT(C40:C42) -> 3 | H43: =SUM(H40:H42) -> 4976 | J43: =SUM(J40:J42) -> 148.08485 | K43: =SUM(K40:K42) -> 28 | L43: =SUM(L40:L42) -> 68 | M43: =SUM(M40:M42) -> 247.58485 | N43: =SUM(N40:N42) -> 3 | O43: =SUM(O40:O42) -> 3.5 | P43: =M43/24 -> 10.316035

Sheet Kostnadsmodeller
A1: faktorer | B1: Valuta | G1: Rute R1 | H1: Segment | I1: Segmenttype | J1: Mode | K1: Fra | L1: Til | M1: Direkte Kostnader | N1: Terminal kostnader | O1: Tidskostnad (VFTTS) | P1: Generaliserte kostnader
A2: VFTTS (kr/time) | B2: 330 | C2: Kilde: De Jong et al. (2004/2007); 30-50 EUR/time for veitransport (konservativt estimat) | H2: 1 | I2: Main haul | J2: Sjø | K2: Karmøy | L2: Rostock | M2: =B4 -> 6188
A3: Rail kostnad pr tonn-km | B3: 0.5 | C3: Kilde: EU RECORDIT (2003); typisk 0.04-0.10 EUR/tonn-km for intermodal Europa | H3: 2 | I3: Main haul | J3: rail1 | K3: Rostock | L3: Bratislava | M3: =$B$3*Ruter!H3*$B$9 -> 14400
A4: Sjø fast kostnad RoRo | B4: 6188 | H4: 3 | I4: Terminal transfer | J4: Truck | K4: Terminal | L4: terminal | M4: =$B$5*Ruter!H4*$B$9 -> 280
A5: Vei kostnad pr tonn-km | B5: =14/$B$9 -> 0.58333333 | C5: Kilde: IRU/Upply Q4 2024 ~€1.20/km ÷ 24t = 0.583 kr/tonn-km | H5: 4 | I5: Main haul | J5: rail2 | K5: Bratislava | L5: Slovenia | M5: =$B$3*Ruter!H5*$B$9 -> 4800
A6: Terminal omlastning | B6: 1688 | H6: 5 | I6: Final haul | J6: rail3 | K6: Slovenia | L6: Beograd | M6: =$B$3*Ruter!H6*$B$9 -> 6000
A7: Simple transfer (Rail→Rail) | B7: 1200 | G7: Totalt | M7: =SUM(M2:M6) -> 31668 | N7: =$B$8*Ruter!N7 -> 5064 | O7: =B2*Ruter!M7 -> 85132.143 | P7: =SUM(M7:O7) -> 121864.14
A8: Complex transfer (Rail→Truck/Sjø) | B8: 1688
A9: Lastemengde (tonn/trailer) | B9: 24 | C9: Kilde: Hydro (e-post, høst 2024); 24-25 tonn avh. av land
G10: Rute R2 | H10: Segment | I10: Segmenttype | J10: Mode | K10: Fra | L10: Til | M10: Direkte Kostnader | N10: Terminal kostnader | O10: Tidskostnad (VFTTS) | P10: Generaliserte kostnader
H11: 1 | I11: Main haul | J11: Sjø | K11: Karmøy | L11: Hamburg | M11: =B4 -> 6188
H12: 2 | I12: Main haul | J12: Rail | K12: Hamburg | L12: München | M12: =$B$3*Ruter!H12*$B$9 -> 10080
H13: 3 | I13: Main haul | J13: Rail | K13: München | L13: Ljubljana | M13: =$B$3*Ruter!H13*$B$9 -> 4800
H14: 4 | I14: Final haul | J14: Rail | K14: Ljubljana | L14: Beograd | M14: =$B$3*Ruter!H14*$B$9 -> 6600
G15: Totalt | M15: =SUM(M11:M14) -> 27668 | N15: =$B$8*Ruter!N15 -> 3376 | O15: =$B$2*Ruter!M15 -> 79610.143 | P15: =SUM(M15:O15) -> 110654.14
G21: Rute R3 | H21: Segment | I21: Segmenttype | J21: Mode | K21: Fra | L21: Til | M21: Direkte Kostnader | N21: Terminal kostnader | O21: Tidskostnad (VFTTS) | P21: Generaliserte kostnader
H22: 1 | J22: Sjø | K22: Karmøy | L22: Rotterdam | M22: =B4 -> 6188
H23: 2 | J23: Rail | K23: Rotterdam | L23: Munchen | M23: =$B$3*Ruter!H23*$B$9 -> 10200
H24: 3 | J24: Rail | K24: Munchen | L24: Ljubljana | M24: =$B$3*Ruter!H24*$B$9 -> 4800
H25: 4 | J25: Rail | K25: Ljubljana | L25: Beograd | M25: =$B$3*Ruter!H25*$B$9 -> 6600
G26: Totalt | M26: =SUM(M22:M25) -> 27788 | N26: =$B$8*Ruter!N26 -> 3376 | O26: =B2*Ruter!M26 -> 77385 | P26: =SUM(M26:O26) -> 108549
G30: Rute R4 | H30: Segment | I30: Segmenttype | J30: Mode | K30: Fra | L30: Til | M30: Direkte Kostnader | N30: Terminal kostnader | O30: Tidskostnad (VFTTS) | P30: Generaliserte kostnader
H31: 1 | J31: Sjø | K31: Karmøy | L31: Rotterdam | M31: =B4 -> 6188
H32: 2 | J32: Rail | K32: Rotterdam | L32: Wien | M32: =$B$3*Ruter!H33*$B$9 -> 13200
H33: 3 | J33: Rail | K33: Wien | L33: Koper | M33: =$B$3*Ruter!H34*$B$9 -> 6000
H34: 4 | J34: Rail | K34: Koper | L34: Beograd | M34: =$B$3*Ruter!H35*$B$9 -> 7200
G35: Totalt | M35: =SUM(M31:M34) -> 32588 | N35: =$B$8*Ruter!N36 -> 3376 | O35: =B2*Ruter!M36 -> 82665 | P35: =SUM(M35:O35) -> 118629
G39: Rute R5 | H39: Segment | I39: Segmenttype | J39: Mode | K39: Fra | L39: Til | M39: Direkte Kostnader | N39: Terminal kostnader | O39: Tidskostnad (VFTTS) | P39: Generaliserte kostnader
H40: 1 | I40: Main haul | J40: Sjø | K40: Karmøy | L40: Rotterdam | M40: =B4 -> 6188
H41: 2 | I41: Main haul | J41: Sjø | K41: Rotterdam | L41: Bar (Montenegro) | M41: =B4 -> 6188
H42: 3 | I42: Final haul | J42: Truck | K42: Bar (Montenegro) | L42: Beograd | M42: =$B$5*Ruter!H42*$B$9 -> 6664
G43: Totalt | M43: =SUM(M40:M42) -> 19040 | N43: =$B$8*Ruter!N43 -> 5064 | O43: =$B$2*Ruter!M43 -> 81703 | P43: =SUM(M43:O43) -> 105807

Sheet Charts
A2: Ruter | B2: Generaliserte kostnader | C2: Omlastninger | D2: Ledetid timer
A3: R1 | B3: =Kostnadsmodeller!P7 -> 121864.14 | C3: =Ruter!N7 -> 3 | D3: =Ruter!M7 -> 257.97619
A4: R2 | B4: =Kostnadsmodeller!P15 -> 110654.14 | C4: =Ruter!N15 -> 2 | D4: =Ruter!M15 -> 241.24286
A5: R3 | B5: =Kostnadsmodeller!P26 -> 108549 | C5: =Ruter!N26 -> 2 | D5: =Ruter!M26 -> 234.5
A6: R4 | B6: =Kostnadsmodeller!P35 -> 118629 | C6: =Ruter!N36 -> 2 | D6: =Ruter!M36 -> 250.5
A7: R5 | B7: =Kostnadsmodeller!P43 -> 105807 | C7: =Ruter!N43 -> 3 | D7: =Ruter!M43 -> 247.58485

Sheet Stokastiske_parametere
A1: STOKASTISKE PARAMETERE FOR MONTE CARLO-SIMULERING
A2: Endre verdier i gule celler for å justere usikkerhet. Python-skriptet leser direkte herfra.
A4: 1. Transporttid pr modus — Lognormal fordeling
A5: Mode | B5: Fordeling | C5: CV (σ/μ) | D5: Kommentar | E5: Kilde
A6: Sjø | B6: lognormal | C6: 0.12 | D6: RoRo short-sea Nordsjøen; værforsinkelser | E6: Andersson et al. (2017); bransjenorm
A7: Sjø_havgaaende | B7: lognormal | C7: 0.15 | D7: Lengre havreise (R5: Rotterdam-Bar); mer væreksp. | E7: Andersson et al. (2017)
A8: rail1 | B8: lognormal | C8: 0.2 | D8: Intermodal jernbane; gods-prio under passasjer | E8: Demiridis & Pyrgidis (2022); Demir et al. (2016)
A9: rail2 | B9: lognormal | C9: 0.2 | D9: Intermodal jernbane; korridoreffekter | E9: Demiridis & Pyrgidis (2022)
A10: rail3 | B10: lognormal | C10: 0.2 | D10: Intermodal jernbane; siste segment til Beograd | E10: Demiridis & Pyrgidis (2022)
A11: Rail | B11: lognormal | C11: 0.2 | D11: Generisk jernbane (R2-R4) | E11: Demiridis & Pyrgidis (2022)
A12: Truck | B12: lognormal | C12: 0.08 | D12: Lastebil; mest forutsigbar mode | E12: de Jong (2014); Janic (2007)
A15: 2. Terminaltid pr modus — Triangulær(min, mode, max) i timer
A16: Mode/segmenttype | B16: Min | C16: Mode (= Excel-verdi) | D16: Max | E16: Kommentar | F16: Kilde
A17: Sjø | B17: 6 | C17: 12 | D17: 24 | E17: Havneoperasjon RoRo; lossing+lasting+dokumentkontroll | F17: Bransjeestimat (Hanssen et al. 2012 indirekte)
A18: Sjø_havgaaende | B18: 8 | C18: 12 | D18: 24 | E18: Større havgående havn (Bar); litt lengre min | F18: Bransjeestimat
A19: Rail | B19: 3 | C19: 6 | D19: 12 | E19: Intermodal kranoperasjon; kø ved kapasitetspress | F19: Wiegmans & Behdani (2018); Mandouri et al. (2023)
A20: rail1 | B20: 3 | C20: 6 | D20: 12 | E20: Som Rail | F20: Wiegmans & Behdani (2018)
A21: rail2 | B21: 3 | C21: 6 | D21: 12 | E21: Som Rail | F21: Wiegmans & Behdani (2018)
A22: rail3 | B22: 2 | C22: 4 | D22: 8 | E22: Sluttterminal; ofte raskere uten videre omlasting | F22: Wiegmans & Behdani (2018)
A23: Truck | B23: 2 | C23: 4 | D23: 8 | E23: Direkte levering eller kort terminalstopp | F23: Janic (2007)
A26: 3. Ventetid pr modus — Uniform[0, 2·mean] i timer
A27: Begrunnelse: Hvis avsender bommer på avgang, ventes til neste. Med periodiske avganger fordeles ventetid uniformt fra 0 til hele headway-tiden (kø-teori, M/D/1 approksimasjon).
A28: Mode | B28: Headway (=2·Excel-mean) timer | C28: Avgangsfrekvens | D28: Kilde
A29: Sjø | B29: 68 | C29: 2-3 avg./uke (Sea-Cargo) | D29: Sea-Cargo AS (2025)
A30: Sjø_havgaaende | B30: 68 | C30: 2-3 avg./uke | D30: Antakelse
A31: Rail | B31: 48 | C31: 7-10 avg./uke | D31: METRANS (2024); Adria Kombi (2025)
A32: rail1 | B32: 48 | C32: Som Rail | D32: METRANS (2024)
A33: rail2 | B33: 48 | C33: Som Rail | D33: METRANS (2024)
A34: rail3 | B34: 48 | C34: Som Rail | D34: METRANS (2024)
A35: Truck | B35: 0 | C35: Ingen fast avgang | D35: Janic (2007)
A38: 4. Grenseforsinkelse — Triangulær(min, mode, max) i timer
A39: Grense | B39: Min | C39: Mode | D39: Max | E39: Kommentar | F39: Kilde
A40: Norge_EU | B40: 0.25 | C40: 0.5 | D40: 1 | E40: EØS; forenklet tollprosedyre | F40: EØS-avtalen
A41: EU_Serbia | B41: 2 | C41: 3 | D41: 5 | E41: Serbia ikke-EU; Horgoš/Batrovci | F41: EU Delegation to Serbia (2019)
A42: Schengen_intern | B42: 0 | C42: 0 | D42: 0 | E42: Ingen kontroll | F42: Schengen-avtalen
A45: 5. Disrupsjons-risiko (sjeldne forsinkelser) — pr segment
A46: Modellerer "long tail risk" (Christopher 2016): liten sannsynlighet for stor forsinkelse. Triangulær fordeling for forsinkelseslengde GITT at hendelse inntreffer.
A47: Mode | B47: P(disrupsjon) pr segment | C47: Forsinkelse min (t) | D47: mode (t) | E47: max (t) | F47: Eksempler
A48: Sjø | B48: 0.05 | C48: 12 | D48: 24 | E48: 72 | F48: Storm, havnestreik
A49: Sjø_havgaaende | B49: 0.05 | C49: 12 | D49: 24 | E49: 72 | F49: Værvindu Middelhavet
...

Sheet Kostnadsparametere_MC
A1: KOSTNADSPARAMETERE FOR GC-BEREGNING
A2: Speiler verdiene i Kostnadsmodeller-arket. Endre i gule celler.
A4: Parameter | B4: Verdi | C4: Enhet | D4: Kilde
A5: VFTTS_alfa | B5: 330 | C5: kr/time | D5: Halse et al. (2019); 13.6 kr/tonn-time × 24 tonn
A6: Reliability_ratio_RR | B6: 0.8 | C6: - | D6: Halse et al. (2019); β = RR · α
A7: Rail_kostnad_per_tonn_km | B7: 0.5 | C7: kr/tonn-km | D7: EU RECORDIT (2003)
A8: Vei_kostnad_per_tonn_km | B8: 0.5833 | C8: kr/tonn-km | D8: IRU/Upply Q4 2024
A9: Sjø_fast_RoRo | B9: 6188 | C9: kr/sending | D9: Bransjeestimat
A10: Terminal_simple | B10: 1200 | C10: kr/omlasting | D10: Wiegmans & Behdani (2018)
A11: Terminal_complex | B11: 1688 | C11: kr/omlasting | D11: Wiegmans & Behdani (2018)
A12: Lastemengde_tonn | B12: 24 | C12: tonn/trailer | D12: Hydro (e-post høst 2024)
A15: Pålitelighetsledd β · σ(t) i GC:
A16: β = RR · α = 0.8 · 330 = 264 kr/time
A17: Brukes til å verdsette redusert ledetidsvariabilitet (Andersson et al. 2017).
