Workbook

Sheet Ruter
A1: RuteID | B1: Rute R1 | C1: Segment | D1: Segmenttype | E1: Mode | F1: Fra | G1: Til | H1: Distanse km | I1: Gj.snitt Hastighet km/t | J1: Transporttid timer | K1: Terminaltid timer | L1: Ventetid (timer) | M1: Segementtid | N1: Lovpålagt hviletid (timer) | O1: Omlastninger | P1: Grenseforsinkelse (timer) | Q1: Dager reist | R1: Headway_t
A2: R1 | C2: 1 | D2: Main haul | E2: Sjø | F2: Karmøy | G2: Rostock | H2: 913 | I2: 28 | J2: =H2/I2 -> 32.607143 | K2: 12 | L2: 34 | M2: =J2+K2+L2+N2+P2 -> 79.107143 | N2: 0 | O2: 1 | P2: 0.5 | R2: 68
A3: R1 | C3: 2 | D3: Main haul | E3: rail1 | F3: Rostock | G3: Bratislava | H3: 1200 | I3: 60 | J3: =H3/I3 -> 20 | K3: 6 | L3: 12 | M3: =J3+K3+L3+N3+P3 -> 40 | N3: 0 | O3: 0 | P3: 2 | R3: 24
A4: R1 | C4: 3 | D4: Terminal transfer | E4: Truck | F4: Terminal | G4: terminal | H4: 20 | I4: 60 | J4: =H4/I4 -> 0.33333333 | K4: 4 | L4: 0 | M4: =J4+K4+L4+N4+P4 -> 4.3333333 | N4: 0 | O4: 1 | P4: 0 | R4: 0
A5: R1 | C5: 4 | D5: Main haul | E5: rail2 | F5: Bratislava | G5: Koper | H5: 450 | I5: 60 | J5: =H5/I5 -> 7.5 | K5: 6 | L5: 12 | M5: =J5+K5+L5+N5+P5 -> 27 | N5: 0 | O5: 0 | P5: 1.5 | R5: 24
A6: R1 | C6: 5 | D6: Final haul | E6: rail3 | F6: Koper | G6: Beograd | H6: 600 | I6: 60 | J6: =H6/I6 -> 10 | K6: 4 | L6: 12 | M6: =J6+K6+L6+N6+P6 -> 31.9 | N6: 0 | O6: 1 | P6: 5.9 | R6: 24
B7: Totalt | C7: =COUNT(C2:C6) -> 5 | H7: =SUM(H2:H6) -> 3183 | J7: =SUM(J2:J6) -> 70.440476 | K7: =SUM(K2:K6) -> 32 | L7: =SUM(L2:L6) -> 70 | M7: =SUM(M2:M6) -> 182.34048 | N7: =SUM(N2:N6) -> 0 | O7: =SUM(O2:O6) -> 3 | P7: =SUM(P2:P6) -> 9.9 | Q7: =M7/24 -> 7.5975198
B10: Rute R2 | C10: Segment | D10: Segmenttype | E10: Mode | F10: Fra | G10: Til | H10: Distanse km | I10: GJ Hastighet km/t | J10: Transporttid timer | K10: Terminaltid timer | L10: Ventetid (timer) | M10: Segementtid | N10: Lovpålagt hviletid (timer) | O10: Omlastninger | P10: Grenseforsinkelse (timer) | Q10: Dager reist
A11: R2 | C11: 1 | D11: Main haul | E11: Sjø | F11: Karmøy | G11: Hamburg | H11: 791 | I11: 28 | J11: =H11/I11 -> 28.25 | K11: 12 | L11: 34 | M11: =J11+K11+L11+N11+P11 -> 74.75 | N11: 0 | O11: 1 | P11: 0.5 | R11: 68
A12: R2 | C12: 2 | D12: Main haul | E12: Rail | F12: Hamburg | G12: München | H12: 840 | I12: 60 | J12: =H12/I12 -> 14 | K12: 6 | L12: 8.5 | M12: =J12+K12+L12+N12+P12 -> 28.5 | N12: 0 | O12: 0 | P12: 0 | R12: 17
A13: R2 | C13: 3 | D13: Main haul | E13: Rail | F13: München | G13: Ljubljana | H13: 400 | I13: 60 | J13: =H13/I13 -> 6.6666667 | K13: 6 | L13: 24 | M13: =J13+K13+L13+N13+P13 -> 38.666667 | N13: 0 | O13: 0 | P13: 2 | R13: 48
A14: R2 | C14: 4 | D14: Final haul | E14: Rail | F14: Ljubljana | G14: Beograd | H14: 530 | I14: 60 | J14: =H14/I14 -> 8.8333333 | K14: 4 | L14: 12 | M14: =J14+K14+L14+N14+P14 -> 30.733333 | N14: 0 | O14: 1 | P14: 5.9 | R14: 24
B15: Totalt | C15: =COUNT(C11:C14) -> 4 | H15: =SUM(H11:H14) -> 2561 | J15: =SUM(J11:J14) -> 57.75 | K15: =SUM(K11:K14) -> 28 | L15: =SUM(L11:L14) -> 78.5 | M15: =SUM(M11:M14) -> 172.65 | N15: =SUM(N11:N14) -> 0 | O15: =SUM(O11:O14) -> 2 | P15: =SUM(P11:P14) -> 8.4 | Q15: =M15/24 -> 7.19375
B21: Rute R3 | C21: Segment | D21: Segmenttype | E21: Mode | F21: Fra | G21: Til | H21: Distanse km | I21: GJ Hastighet km/t | J21: Transporttid timer | K21: Terminaltid timer | L21: Ventetid (timer) | M21: Segementtid | N21: Lovpålagt hviletid (timer) | O21: Omlastninger | P21: Grenseforsinkelse (timer) | Q21: Dager reist
A22: R3 | C22: 1 | E22: Sjø | F22: Karmøy | G22: Rotterdam | H22: 867 | I22: 28 | J22: =H22/I22 -> 30.964286 | K22: 12 | L22: 34 | M22: =J22+K22+L22+N22+P22 -> 77.464286 | N22: 0 | O22: 1 | P22: 0.5 | R22: 68
A23: R3 | C23: 2 | E23: Rail | F23: Rotterdam | G23: Munchen | H23: 850 | I23: 60 | J23: =H23/I23 -> 14.166667 | K23: 6 | L23: 42 | M23: =J23+K23+L23+N23+P23 -> 62.666667 | N23: 0 | O23: 0 | P23: 0.5 | R23: 84
A24: R3 | C24: 3 | E24: Rail | F24: Munchen | G24: Ljubljana | H24: 400 | I24: 60 | J24: =H24/I24 -> 6.6666667 | K24: 6 | L24: 24 | M24: =J24+K24+L24+N24+P24 -> 38.666667 | N24: 0 | O24: 0 | P24: 2 | R24: 48
A25: R3 | C25: 4 | E25: Rail | F25: Ljubljana | G25: Beograd | H25: 530 | I25: 60 | J25: =H25/I25 -> 8.8333333 | K25: 4 | L25: 12 | M25: =J25+K25+L25+N25+P25 -> 30.733333 | N25: 0 | O25: 1 | P25: 5.9 | R25: 24
B26: Totalt | H26: =SUM(H22:H25) -> 2647 | J26: =SUM(J22:J25) -> 60.630952 | K26: =SUM(K22:K25) -> 28 | L26: =SUM(L22:L25) -> 112 | M26: =SUM(M22:M25) -> 209.53095 | N26: =SUM(N22:N25) -> 0 | O26: =SUM(O22:O25) -> 2 | P26: =SUM(P22:P25) -> 8.9 | Q26: =M26/24 -> 8.7304563
B31: Rute R4 | C31: Segment | D31: Segmenttype | E31: Mode | F31: Fra | G31: Til | H31: Distanse km | I31: GJ Hastighet km/t | J31: Transporttid timer | K31: Terminaltid timer | L31: Ventetid (timer) | M31: Segementtid | N31: Lovpålagt hviletid (timer) | O31: Omlastninger | P31: Grenseforsinkelse (timer) | Q31: Dager reist
A32: R4 | C32: 1 | E32: Sjø | F32: Karmøy | G32: Rotterdam | H32: 867 | I32: 28 | J32: =H32/I32 -> 30.964286 | K32: 12 | L32: 34 | M32: =J32+K32+L32+N32+P32 -> 77.464286 | N32: 0 | O32: 1 | P32: 0.5 | R32: 68
A33: R4 | C33: 2 | E33: Rail | F33: Rotterdam | G33: Wien | H33: 1100 | I33: 60 | J33: =H33/I33 -> 18.333333 | K33: 6 | L33: 16.5 | M33: =J33+K33+L33+N33+P33 -> 41.833333 | N33: 0 | O33: 0 | P33: 1 | R33: 33
A34: R4 | C34: 3 | E34: Rail | F34: Wien | G34: Ljubljana | H34: 480 | I34: 60 | J34: =H34/I34 -> 8 | K34: 6 | L34: 12 | M34: =J34+K34+L34+N34+P34 -> 27.5 | N34: 0 | O34: 0 | P34: 1.5 | R34: 24
A35: R4 | C35: 4 | E35: Rail | F35: Ljubljana | G35: Beograd | H35: 530 | I35: 60 | J35: =H35/I35 -> 8.8333333 | K35: 4 | L35: 12 | M35: =J35+K35+L35+N35+P35 -> 30.733333 | N35: 0 | O35: 1 | P35: 5.9 | R35: 24
B36: Totalt | H36: =SUM(H32:H35) -> 2977 | J36: =SUM(J32:J35) -> 66.130952 | K36: =SUM(K32:K35) -> 28 | L36: =SUM(L32:L35) -> 74.5 | M36: =SUM(M32:M35) -> 177.53095 | N36: =SUM(N32:N35) -> 0 | O36: =SUM(O32:O35) -> 2 | P36: =SUM(P32:P35) -> 8.9 | Q36: =M36/24 -> 7.397123
B39: Rute R5 | C39: Segment | D39: Segmenttype | E39: Mode | F39: Fra | G39: Til | H39: Distanse km | I39: GJ Hastighet km/t | J39: Transporttid timer | K39: Terminaltid timer | L39: Ventetid (timer) | M39: Segementtid | N39: Lovpålagt hviletid (timer) | O39: Omlastninger | P39: Grenseforsinkelse (timer) | Q39: Dager reist
A40: R5 | C40: 1 | D40: Main haul | E40: Sjø | F40: Karmøy | G40: Rotterdam | H40: 867 | I40: 28 | J40: =H40/I40 -> 30.964286 | K40: 12 | L40: 34 | M40: =J40+K40+L40+N40+P40 -> 77.464286 | N40: 0 | O40: 1 | P40: 0.5 | R40: 68
A41: R5 | C41: 2 | D41: Main haul | E41: Sjø | F41: Rotterdam | G41: Bar (Montenegro) | H41: 5130 | I41: 33 | J41: =H41/I41 -> 155.45455 | K41: 12 | L41: 34 | M41: =J41+K41+L41+N41+P41 -> 201.95455 | N41: 0 | O41: 0 | P41: 0.5 | R41: 68
A42: R5 | C42: 3 | D42: Final haul | E42: Truck | F42: Bar (Montenegro) | G42: Beograd | H42: 476 | I42: 80 | J42: =H42/I42 -> 5.95 | K42: 4 | L42: 0 | M42: =J42+K42+L42+N42+P42 -> 12.95 | N42: 0 | O42: 1 | P42: 3 | R42: 0
B43: Totalt | C43: =COUNT(C40:C42) -> 3 | H43: =SUM(H40:H42) -> 6473 | J43: =SUM(J40:J42) -> 192.36883 | K43: =SUM(K40:K42) -> 28 | L43: =SUM(L40:L42) -> 68 | M43: =SUM(M40:M42) -> 292.36883 | N43: =SUM(N40:N42) -> 0 | O43: =SUM(O40:O42) -> 2 | P43: =SUM(P40:P42) -> 4 | Q43: =M43/24 -> 12.182035
B46: Rute R6 | C46: Segment | D46: Segmenttype | E46: Mode | F46: Fra | G46: Til | H46: Distanse km | I46: GJ Hastighet km/t | J46: Transporttid timer | K46: Terminaltid timer | L46: Ventetid (timer) | M46: Segementtid | N46: Lovpålagt hviletid (timer) | O46: Omlastninger | P46: Grenseforsinkelse (timer) | Q46: Dager reist
A47: R6 | C47: 1 | D47: Main haul | E47: Sjø | F47: Karmøy | G47: Rotterdam | H47: 867 | I47: 28 | J47: =H47/I47 -> 30.964286 | K47: 12 | L47: 34 | M47: =J47+K47+L47+N47+P47 -> 77.464286 | N47: 0 | O47: 1 | P47: 0.5 | R47: 68
A48: R6 | C48: 2 | D48: Final haul | E48: Truck | F48: Rotterdam | G48: Beograd | H48: 1780 | I48: 80 | J48: =H48/I48 -> 22.25 | K48: 4 | L48: 0 | M48: =J48+K48+L48+N48+P48 -> 63.75 | N48: 33 | O48: 0 | P48: 4.5 | R48: 0
B49: Totalt | C49: =COUNT(C47:C48) -> 2 | H49: =SUM(H47:H48) -> 2647 | J49: =SUM(J47:J48) -> 53.214286 | K49: =SUM(K47:K48) -> 16 | L49: =SUM(L47:L48) -> 34 | M49: =SUM(M47:M48) -> 141.21429 | N49: =SUM(N47:N48) -> 33 | O49: =SUM(O47:O48) -> 1 | P49: =SUM(P47:P48) -> 5 | Q49: =M49/24 -> 5.8839286

Sheet Kostnadsmodeller
A1: faktorer | B1: Valuta | G1: Rute R1 | H1: Segment | I1: Segmenttype | J1: Mode | K1: Fra | L1: Til | M1: Direkte Kostnader | N1: Terminal kostnader | O1: Tidskostnad (VFTTS) | P1: Generaliserte kostnader
A2: VFTTS (kr/time) | B2: 330 | H2: 1 | I2: Main haul | J2: Sjø | K2: Karmøy | L2: Rostock | M2: =B4*Ruter!H2 -> 6391
A3: Rail kostnad pr tonn-km | B3: 0.5 | H3: 2 | I3: Main haul | J3: rail1 | K3: Rostock | L3: Bratislava | M3: =$B$3*Ruter!H3*$B$9 -> 14400
A4: Sjø kostnad pr kilometer - RoRo | B4: 7 | H4: 3 | I4: Terminal transfer | J4: Truck | K4: Terminal | L4: terminal | M4: =$B$5*Ruter!H4*$B$9 -> 360
A5: Vei kostnad pr tonn-km | B5: 0.75 | H5: 4 | I5: Main haul | J5: rail2 | K5: Bratislava | L5: Slovenia | M5: =$B$3*Ruter!H5*$B$9 -> 5400
A6: Terminal omlastning | B6: 1000 | H6: 5 | I6: Final haul | J6: rail3 | K6: Slovenia | L6: Beograd | M6: =$B$3*Ruter!H6*$B$9 -> 7200
A7: Simple transfer (Rail→Rail) | B7: 0 | G7: Totalt | M7: =SUM(M2:M6) -> 33751 | N7: =$B$8*Ruter!O7 -> 3000 | O7: =B2*Ruter!M7 -> 60172.357 | P7: =SUM(M7:O7) -> 96923.357
A8: Complex transfer (Rail→Truck/Sjø) | B8: 1000
A9: Lastemengde (tonn/trailer) | B9: 24
G10: Rute R2 | H10: Segment | I10: Segmenttype | J10: Mode | K10: Fra | L10: Til | M10: Direkte Kostnader | N10: Terminal kostnader | O10: Tidskostnad (VFTTS) | P10: Generaliserte kostnader
H11: 1 | I11: Main haul | J11: Sjø | K11: Karmøy | L11: Hamburg | M11: =B4*Ruter!H11 -> 5537
H12: 2 | I12: Main haul | J12: Rail | K12: Hamburg | L12: München | M12: =$B$3*Ruter!H12*$B$9 -> 10080
H13: 3 | I13: Main haul | J13: Rail | K13: München | L13: Ljubljana | M13: =$B$3*Ruter!H13*$B$9 -> 4800
H14: 4 | I14: Final haul | J14: Rail | K14: Ljubljana | L14: Beograd | M14: =$B$3*Ruter!H14*$B$9 -> 6360
G15: Totalt | M15: =SUM(M11:M14) -> 26777 | N15: =$B$8*Ruter!O15 -> 2000 | O15: =$B$2*Ruter!M15 -> 56974.5 | P15: =SUM(M15:O15) -> 85751.5
G21: Rute R3 | H21: Segment | I21: Segmenttype | J21: Mode | K21: Fra | L21: Til | M21: Direkte Kostnader | N21: Terminal kostnader | O21: Tidskostnad (VFTTS) | P21: Generaliserte kostnader
H22: 1 | J22: Sjø | K22: Karmøy | L22: Rotterdam | M22: =B4*Ruter!H22 -> 6069
H23: 2 | J23: Rail | K23: Rotterdam | L23: Munchen | M23: =$B$3*Ruter!H23*$B$9 -> 10200
H24: 3 | J24: Rail | K24: Munchen | L24: Ljubljana | M24: =$B$3*Ruter!H24*$B$9 -> 4800
H25: 4 | J25: Rail | K25: Ljubljana | L25: Beograd | M25: =$B$3*Ruter!H25*$B$9 -> 6360
G26: Totalt | M26: =SUM(M22:M25) -> 27429 | N26: =$B$8*Ruter!O26 -> 2000 | O26: =B2*Ruter!M26 -> 69145.214 | P26: =SUM(M26:O26) -> 98574.214
G30: Rute R4 | H30: Segment | I30: Segmenttype | J30: Mode | K30: Fra | L30: Til | M30: Direkte Kostnader | N30: Terminal kostnader | O30: Tidskostnad (VFTTS) | P30: Generaliserte kostnader
H31: 1 | J31: Sjø | K31: Karmøy | L31: Rotterdam | M31: =B4*Ruter!H32 -> 6069
H32: 2 | J32: Rail | K32: Rotterdam | L32: Wien | M32: =$B$3*Ruter!H33*$B$9 -> 13200
H33: 3 | J33: Rail | K33: Wien | L33: Koper | M33: =$B$3*Ruter!H34*$B$9 -> 5760
H34: 4 | J34: Rail | K34: Koper | L34: Beograd | M34: =$B$3*Ruter!H35*$B$9 -> 6360
G35: Totalt | M35: =SUM(M31:M34) -> 31389 | N35: =$B$8*Ruter!O36 -> 2000 | O35: =B2*Ruter!M36 -> 58585.214 | P35: =SUM(M35:O35) -> 91974.214
G39: Rute R5 | H39: Segment | I39: Segmenttype | J39: Mode | K39: Fra | L39: Til | M39: Direkte Kostnader | N39: Terminal kostnader | O39: Tidskostnad (VFTTS) | P39: Generaliserte kostnader
H40: 1 | I40: Main haul | J40: Sjø | K40: Karmøy | L40: Rotterdam | M40: =B4*Ruter!H40 -> 6069
H41: 2 | I41: Main haul | J41: Sjø | K41: Rotterdam | L41: Bar (Montenegro) | M41: =B4*Ruter!H41 -> 35910
H42: 3 | I42: Final haul | J42: Truck | K42: Bar (Montenegro) | L42: Beograd | M42: =$B$5*Ruter!H42*$B$9 -> 8568
G43: Totalt | M43: =SUM(M40:M42) -> 50547 | N43: =$B$8*Ruter!O43 -> 2000 | O43: =$B$2*Ruter!M43 -> 96481.714 | P43: =SUM(M43:O43) -> 149028.71
G47: Rute R6 | H47: Segment | I47: Segmenttype | J47: Mode | K47: Fra | L47: Til | M47: Direkte Kostnader | N47: Terminal kostnader | O47: Tidskostnad (VFTTS) | P47: Generaliserte kostnader
H48: 1 | I48: Main haul | J48: Sjø | K48: Karmøy | L48: Rotterdam | M48: =B4*Ruter!H47 -> 6069
H49: 2 | I49: Final haul | J49: Truck | K49: Rotterdam | L49: Beograd | M49: =$B$5*Ruter!H48*$B$9 -> 32040
G50: Totalt | M50: =SUM(M48:M49) -> 38109 | N50: 1000 | O50: 49279.113 | P50: =SUM(M50:O50) -> 88388.113

Sheet Charts
A2: Ruter | B2: Generaliserte kostnader | C2: Omlastninger | D2: Ledetid timer
A3: R1 | B3: =Kostnadsmodeller!P7 -> 96923.357 | C3: =Ruter!O7 -> 3 | D3: =Ruter!M7 -> 182.34048
A4: R2 | B4: =Kostnadsmodeller!P15 -> 85751.5 | C4: =Ruter!O15 -> 2 | D4: =Ruter!M15 -> 172.65
A5: R3 | B5: =Kostnadsmodeller!P26 -> 98574.214 | C5: =Ruter!O26 -> 2 | D5: =Ruter!M26 -> 209.53095
A6: R4 | B6: =Kostnadsmodeller!P35 -> 91974.214 | C6: =Ruter!O36 -> 2 | D6: =Ruter!M36 -> 177.53095
A7: R5 | B7: =Kostnadsmodeller!P43 -> 149028.71 | C7: =Ruter!O43 -> 2 | D7: =Ruter!M43 -> 292.36883
A8: R6 | B8: =Kostnadsmodeller!P50 -> 88388.113 | C8: =Ruter!O49 -> 1 | D8: =Ruter!M49 -> 141.21429

Sheet Stokastiske_parametere
A1: STOKASTISKE PARAMETERE FOR MONTE CARLO-SIMULERING
A2: Endre verdier i gule celler for å justere usikkerhet. Python-skriptet leser direkte herfra.
A4: 1. Transporttid pr modus — Lognormal fordeling
A5: Mode | B5: Fordeling | C5: CV (σ/μ) | D5: Kommentar
A6: Sjø | B6: lognormal | C6: 0.12 | D6: RoRo short-sea Nordsjøen; værforsinkelser
A7: Sjø_havgaaende | B7: lognormal | C7: 0.15 | D7: Lengre havreise (R5: Rotterdam-Bar); mer væreksp.
A8: Rail | B8: lognormal | C8: 0.2 | D8: Generisk jernbane (R2-R4)
A9: Truck | B9: lognormal | C9: 0.08 | D9: Lastebil; mest forutsigbar mode
A12: 2. Terminaltid pr modus — Triangulær(min, mode, max) i timer
A13: Mode/segmenttype | B13: Min | C13: Mode (= Excel-verdi) | D13: Max | E13: Kommentar | F13: Kilde
A14: Sjø | B14: 6 | C14: 12 | D14: 24 | E14: Havneoperasjon RoRo; lossing+lasting+dokumentkontroll | F14: Bransjeestimat (Hanssen et al. 2012 indirekte)
A15: Sjø_havgaaende | B15: 8 | C15: 12 | D15: 24 | E15: Større havgående havn (Bar); litt lengre min | F15: Bransjeestimat
A16: Rail | B16: 3 | C16: 6 | D16: 12 | E16: Intermodal kranoperasjon; kø ved kapasitetspress | F16: Wiegmans & Behdani (2018); Mandouri et al. (2023)
A17: Truck | B17: 2 | C17: 4 | D17: 8 | E17: Direkte levering eller kort terminalstopp | F17: Janic (2007)
A20: 3. Ventetid — Uniform[0, headway] per segment (mean = headway/2)
A21: Headway hentes per segment fra kol R i Ruter-arket (empirisk: ERS, Adria Kombi, HUPAC, METRANS, RD/AWB PaP)
A22: Mode | B22: Headway (=2·Excel-mean) timer | C22: Avgangsfrekvens | D22: Kilde
A23: Sjø | B23: 68 | C23: 2-3 avg./uke (Sea-Cargo) | D23: Sea-Cargo AS (2025)
A24: Sjø_havgaaende | B24: 68 | C24: 2-3 avg./uke | D24: Antakelse
A25: Rail | B25: 48 | C25: 7-10 avg./uke | D25: METRANS (2024); Adria Kombi (2025)
A26: Truck | B26: 0 | C26: Ingen fast avgang | D26: Janic (2007)
A29: 4. Grenseforsinkelse — Triangulær(min, mode, max) i timer per landpar
A30: Landpar | B30: Min | C30: Mode | D30: Max | E30: Kommentar | F30: Kilde
A31: NO-EU | B31: 0.25 | C31: 0.5 | D31: 1 | E31: Karmøy export-klarering | F31: Antagelse
A32: AT-SLO | B32: 0.5 | C32: 1.5 | D32: 3 | E32: Spielfeld/Jesenice | F32: AWB RFC bottleneck
A33: SLO-CRO | B33: 1 | C33: 1.5 | D33: 3 | E33: Dobova; PaP 1:37, real 2x | F33: AWB RFC PaP TT2027
A34: CRO-SRB | B34: 3 | C34: 4.4 | D34: 8 | E34: Šid/Tovarnik EU-grense + lokoskift | F34: AWB RFC PaP NP7
A35: DE-CZ | B35: 0.5 | C35: 1 | D35: 2 | E35: Bad Schandau/Děčín | F35: RD RFC PaP
A36: CZ-SK | B36: 0.5 | C36: 1 | D36: 2 | E36: Břeclav | F36: RD RFC PaP
A37: SK-AT | B37: 0.25 | C37: 0.5 | D37: 1 | E37: Marchegg Schengen-internt | F37: Antagelse
A38: NL-DE | B38: 0.25 | C38: 0.5 | D38: 1 | E38: Bad Bentheim Schengen | F38: Antagelse
A39: DE-AT | B39: 0.25 | C39: 0.5 | D39: 1 | E39: Salzburg Schengen | F39: Antagelse
A40: MNE-SRB | B40: 0.5 | C40: 1.5 | D40: 3 | E40: Bar-Beograd ikke-EU | F40: Antagelse
A45: 6. Monte Carlo-innstillinger
A46: Parameter
A47: N_simuleringer | B47: 10000 | C47: Antall iterasjoner pr rute. 10k gir stabile P10/P90.
A48: Random_seed | B48: 42 | C48: For reproduserbare resultater. Endre for nye trekkrunder.
A49: Inkluder_disrupsjoner | B49: 0 | C49: 1 = ja, 0 = nei. Slå av for å se ren operasjonell variasjon.
A60: 7. Operasjonell buffer for truck — Triangulær(min, mode, max) i timer
A61: Småforsinkelser truck: kø/trafikk, ferging, dokumentkontroll, kortere lossing/lasting-vinduer, sjåførbytte, etc. Pr 1000 km kjøring.
...

Sheet Kostnadsparametere_MC
A1: KOSTNADSPARAMETERE FOR GC-BEREGNING
A2: Speiler verdiene i Kostnadsmodeller-arket. Endre i gule celler.
A4: Parameter | B4: Verdi | C4: Enhet | D4: Kilde
A5: VFTTS_alfa | B5: 330 | C5: kr/time | D5: Halse et al. (2019); 13.6 kr/tonn-time × 24 tonn
A6: Reliability_ratio_RR | B6: 0.8 | C6: - | D6: Halse et al. (2019); β = RR · α
A7: Rail_kostnad_per_tonn_km | B7: 0.5 | C7: kr/tonn-km | D7: EU RECORDIT (2003)
A8: Vei_kostnad_per_tonn_km | B8: 0.75 | C8: kr/tonn-km | D8: IRU/Upply Q4 2024
A9: Sjø_kostnad_per_km | B9: 7 | C9: kr/km | D9: UNCTAD (2023); RoRo-bransje 5-10 kr/km, midtpunkt
A10: Terminal_simple | B10: 0 | C10: kr/omlasting | D10: Wiegmans & Behdani (2018)
A11: Terminal_complex | B11: 1000 | C11: kr/omlasting | D11: Wiegmans & Behdani (2018)
A12: Lastemengde_tonn | B12: 24 | C12: tonn/trailer | D12: Hydro (e-post høst 2024)
A15: Pålitelighetsledd β · σ(t) i GC:
A16: β = RR · α = 0.8 · 330 = 264 kr/time
A17: Brukes til å verdsette redusert ledetidsvariabilitet (Andersson et al. 2017).
